const n2 = 12

try {
 n2 = 14
}
catch (err){
    console.log(`Error: ${err}`);
}